Workbook

Sheet Sales_Data
A1: Row ID | B1: Order ID | C1: Order Date | D1: Ship Date | E1: Ship Mode | F1: Customer Name | G1: Segment | H1: Region | I1: State | J1: City | K1: Category | L1: Sub-Category | M1: Product Name | N1: Quantity | O1: Discount | P1: Sales | Q1: Profit | S1: Cleaning log (Task 1): started with 545 rows in Raw_Data -> removed 10 blank rows, 21 duplicate rows, and rows with missing Sales/Profit or unparseable dates -> 510 clean rows remain here. Order Date & Ship Date formatted as dates; Sales & Profit formatted as currency.
A2: 1 | B2: ES-2021-100001 | C2: 44482 | D2: 44488 | E2: Second Class | F2: James Williams | G2: Consumer | H2: East | I2: New York | J2: New York City | K2: Office Supplies | L2: Paper | M2: Copy Paper A4 | N2: 2 | O2: 0 | P2: 163.7 | Q2: 17.07
A3: 2 | B3: ES-2023-100002 | C3: 45116 | D3: 45121 | E3: Second Class | F3: Jessica Hernandez | G3: Corporate | H3: East | I3: Virginia | J3: Richmond | K3: Furniture | L3: Furnishings | M3: Wall Clock | N3: 5 | O3: 0 | P3: 2856.83 | Q3: 586.46
A4: 3 | B4: WS-2023-100003 | C4: 44932 | D4: 44939 | E4: First Class | F4: Richard Williams | G4: Home Office | H4: West | I4: Oregon | J4: Portland | K4: Furniture | L4: Furnishings | M4: Desk Lamp | N4: 6 | O4: 0 | P4: 2595.09 | Q4: 487.46
A5: 4 | B5: CS-2024-100004 | C5: 45551 | D5: 45553 | E5: First Class | F5: Richard Rodriguez | G5: Corporate | H5: Central | I5: Minnesota | J5: Minneapolis | K5: Furniture | L5: Chairs | M5: Executive Leather Chair | N5: 13 | O5: 0 | P5: 2864.38 | Q5: 753.88
A6: 5 | B6: WS-2024-100005 | C6: 45634 | D6: 45640 | E6: First Class | F6: Linda Anderson | G6: Corporate | H6: West | I6: Oregon | J6: Portland | K6: Office Supplies | L6: Fasteners | M6: Paper Clips | N6: 11 | O6: 0 | P6: 114.68 | Q6: 8.08
A7: 6 | B7: WT-2021-100006 | C7: 44262 | D7: 44269 | E7: Same Day | F7: Michael Thomas | G7: Corporate | H7: West | I7: Oregon | J7: Portland | K7: Technology | L7: Phones | M7: Smartphone X200 | N7: 6 | O7: 0 | P7: 1311.28 | Q7: -161.83
A8: 7 | B8: WS-2024-100007 | C8: 45394 | D8: 45398 | E8: Standard Class | F8: Thomas Thomas | G8: Consumer | H8: West | I8: Oregon | J8: Portland | K8: Furniture | L8: Bookcases | M8: Corner Bookcase | N8: 10 | O8: 0.1 | P8: 2857.57 | Q8: 995.56
A9: 8 | B9: ES-2024-100008 | C9: 45418 | D9: 45419 | E9: First Class | F9: Patricia Moore | G9: Corporate | H9: East | I9: Pennsylvania | J9: Philadelphia | K9: Office Supplies | L9: Fasteners | M9: Paper Clips | N9: 7 | O9: 0.4 | P9: 289.71 | Q9: 19.55
A10: 9 | B10: ET-2022-100009 | C10: 44736 | D10: 44741 | E10: Second Class | F10: Thomas Martin | G10: Consumer | H10: East | I10: New Jersey | J10: Newark | K10: Office Supplies | L10: Art | M10: Sketch Pad | N10: 13 | O10: 0 | P10: 300.05 | Q10: 81.71
A11: 10 | B11: CT-2024-100010 | C11: 45423 | D11: 45426 | E11: Standard Class | F11: Barbara Johnson | G11: Consumer | H11: Central | I11: Texas | J11: Dallas | K11: Office Supplies | L11: Labels | M11: Address Labels | N11: 8 | O11: 0.2 | P11: 32.32 | Q11: 8.96
A12: 11 | B12: ES-2024-100011 | C12: 45548 | D12: 45552 | E12: First Class | F12: Elizabeth Gonzalez | G12: Home Office | H12: East | I12: Massachusetts | J12: Boston | K12: Technology | L12: Machines | M12: Label Maker | N12: 9 | O12: 0.3 | P12: 881.32 | Q12: 289.62
A13: 12 | B13: SS-2021-100012 | C13: 44328 | D13: 44331 | E13: Standard Class | F13: John Johnson | G13: Consumer | H13: South | I13: Alabama | J13: Birmingham | K13: Office Supplies | L13: Paper | M13: Copy Paper A4 | N13: 1 | O13: 0.1 | P13: 69.28 | Q13: 7.14
... A511: 510 | B511: ET-2023-100483 | C511: 45018 | D511: 45023 | E511: Standard Class | F511: Linda Jackson | G511: Consumer | H511: East | I511: Massachusetts | J511: Boston | K511: Furniture | L511: Tables | M511: Round Conference Table | N511: 7 | O511: 0 | P511: 3011.86 | Q511: -592.02

Sheet Raw_Data
A1: Row ID | B1: Order ID | C1: Order Date | D1: Ship Date | E1: Ship Mode | F1: Customer Name | G1: Segment | H1: Region | I1: State | J1: City | K1: Category | L1: Sub-Category | M1: Product Name | N1: Quantity | O1: Discount | P1: Sales | Q1: Profit | S1: This is the ORIGINAL, unprocessed export (kept for audit). It contains 10 fully blank rows and 21 duplicate rows, plus a few missing Sales values and inconsistent date formats — these were fixed in the 'Sales_Data' sheet (Task 1).
A2: 1 | B2: ES-2021-100001 | C2: 10/13/2021 | D2: 10/19/2021 | E2: Second Class | F2: James Williams | G2: Consumer | H2: East | I2: New York | J2: New York City | K2: Office Supplies | L2: Paper | M2: Copy Paper A4 | N2: 2 | O2: 0 | P2: 163.7 | Q2: 17.07
A3: 2 | B3: ES-2023-100002 | C3: 07/09/2023 | D3: 07/14/2023 | E3: Second Class | F3: Jessica Hernandez | G3: Corporate | H3: East | I3: Virginia | J3: Richmond | K3: Furniture | L3: Furnishings | M3: Wall Clock | N3: 5 | O3: 0 | P3: 2856.83 | Q3: 586.46
A4: 3 | B4: WS-2023-100003 | C4: 01/06/2023 | D4: 01/13/2023 | E4: First Class | F4: Richard Williams | G4: Home Office | H4: West | I4: Oregon | J4: Portland | K4: Furniture | L4: Furnishings | M4: Desk Lamp | N4: 6 | O4: 0 | P4: 2595.09 | Q4: 487.46
A5: 4 | B5: CS-2024-100004 | C5: 09/16/2024 | D5: 09/18/2024 | E5: First Class | F5: Richard Rodriguez | G5: Corporate | H5: Central | I5: Minnesota | J5: Minneapolis | K5: Furniture | L5: Chairs | M5: Executive Leather Chair | N5: 13 | O5: 0 | P5: 2864.38 | Q5: 753.88
A6: 5 | B6: WS-2024-100005 | C6: 12/08/2024 | D6: 12/14/2024 | E6: First Class | F6: Linda Anderson | G6: Corporate | H6: West | I6: Oregon | J6: Portland | K6: Office Supplies | L6: Fasteners | M6: Paper Clips | N6: 11 | O6: 0 | P6: 114.68 | Q6: 8.08
A7: 6 | B7: WT-2021-100006 | C7: 03/07/2021 | D7: 03/14/2021 | E7: Same Day | F7: Michael Thomas | G7: Corporate | H7: West | I7: Oregon | J7: Portland | K7: Technology | L7: Phones | M7: Smartphone X200 | N7: 6 | O7: 0 | P7: 1311.28 | Q7: -161.83
A8: 7 | B8: WS-2024-100007 | C8: 04/12/2024 | D8: 04/16/2024 | E8: Standard Class | F8: Thomas Thomas | G8: Consumer | H8: West | I8: Oregon | J8: Portland | K8: Furniture | L8: Bookcases | M8: Corner Bookcase | N8: 10 | O8: 0.1 | P8: 2857.57 | Q8: 995.56
A9: 8 | B9: ES-2024-100008 | C9: 05/06/2024 | D9: 05/07/2024 | E9: First Class | F9: Patricia Moore | G9: Corporate | H9: East | I9: Pennsylvania | J9: Philadelphia | K9: Office Supplies | L9: Fasteners | M9: Paper Clips | N9: 7 | O9: 0.4 | P9: 289.71 | Q9: 19.55
A10: 9 | B10: ET-2022-100009 | C10: 06/24/2022 | D10: 06/29/2022 | E10: Second Class | F10: Thomas Martin | G10: Consumer | H10: East | I10: New Jersey | J10: Newark | K10: Office Supplies | L10: Art | M10: Sketch Pad | N10: 13 | O10: 0 | P10: 300.05 | Q10: 81.71
A11: 10 | B11: CT-2024-100010 | C11: 05/11/2024 | D11: 05/14/2024 | E11: Standard Class | F11: Barbara Johnson | G11: Consumer | H11: Central | I11: Texas | J11: Dallas | K11: Office Supplies | L11: Labels | M11: Address Labels | N11: 8 | O11: 0.2 | P11: 32.32 | Q11: 8.96
A12: 11 | B12: ES-2024-100011 | C12: 09/13/2024 | D12: 09/17/2024 | E12: First Class | F12: Elizabeth Gonzalez | G12: Home Office | H12: East | I12: Massachusetts | J12: Boston | K12: Technology | L12: Machines | M12: Label Maker | N12: 9 | O12: 0.3 | P12: 881.32 | Q12: 289.62
A13: 12 | B13: SS-2021-100012 | C13: 05/12/2021 | D13: 05/15/2021 | E13: Standard Class | F13: John Johnson | G13: Consumer | H13: South | I13: Alabama | J13: Birmingham | K13: Office Supplies | L13: Paper | M13: Copy Paper A4 | N13: 1 | O13: 0.1 | P13: 69.28 | Q13: 7.14
... A139: 138 | B139: WS-2022-100138 | C139: 11/09/2022 | D139: 11/11/2022 | E139: Second Class | F139: David Martinez | G139: Home Office | H139: West | I139: Arizona | J139: Phoenix | K139: Office Supplies | L139: Paper | M139: Copy Paper A4 | N139: 12 | O139: 0.15 | P139: 643.5 | Q139: 116.58
A140: 139 | B140: WS-2023-100139 | C140: 2023-11-22 | D140: 11/25/2023 | E140: Standard Class | F140: Sarah Hernandez | G140: Consumer | H140: West | I140: Arizona | J140: Phoenix | K140: Technology | L140: Copiers | M140: Office Copier Pro | N140: 2 | O140: 0 | Q140: -60.77
A141: 140 | B141: CS-2022-100140 | C141: 09/11/2022 | D141: 09/16/2022 | E141: First Class | F141: Mary Brown | G141: Corporate | H141: Central | I141: Ohio | J141: Columbus | K141: Office Supplies | L141: Storage | M141: Filing Cabinet | N141: 12 | O141: 0.15 | P141: 797.61 | Q141: 113.43
A142: 141 | B142: WS-2024-100141 | C142: 11/14/2024 | D142: 11/15/2024 | E142: Second Class | F142: Barbara Jones | G142: Corporate | H142: West | I142: Nevada | J142: Las Vegas | K142: Office Supplies | L142: Fasteners | M142: Paper Clips | N142: 11 | O142: 0.15 | P142: 1156.64 | Q142: -34.09
A143: 142 | B143: SS-2023-100142 | C143: 08/23/2023 | D143: 08/30/2023 | E143: First Class | F143: Thomas Anderson | G143: Home Office | H143: South | I143: Alabama | J143: Birmingham | K143: Office Supplies | L143: Fasteners | M143: Stapler | N143: 9 | O143: 0.1 | P143: 843.63 | Q143: 174.73
A144: 143 | B144: ET-2021-100143 | C144: 12/03/2021 | D144: 12/06/2021 | E144: Standard Class | F144: John Taylor | G144: Corporate | H144: East | I144: Virginia | J144: Richmond | K144: Furniture | L144: Tables | M144: Rectangular Desk | N144: 14 | O144: 0 | P144: 5267.23 | Q144: 833.16
A145: 144 | B145: ST-2021-100144 | C145: 04/29/2021 | D145: 05/04/2021 | E145: Second Class | F145: William Smith | G145: Home Office | H145: South | I145: Georgia | J145: Atlanta | K145: Office Supplies | L145: Art | M145: Highlighter Pack | N145: 8 | O145: 0.15 | P145: 621.79 | Q145: 114.39
A146: 145 | B146: ET-2024-100145 | C146: 01/14/2024 | D146: 01/15/2024 | E146: Same Day | F146: Linda Jones | G146: Home Office | H146: East | I146: New York | J146: New York City | K146: Office Supplies | L146: Fasteners | M146: Push Pins | N146: 2 | O146: 0.4 | P146: 208.32 | Q146: -48.11
A147: 146 | B147: CT-2021-100146 | C147: 06/14/2021 | D147: 06/20/2021 | E147: Same Day | F147: Patricia Garcia | G147: Home Office | H147: Central | I147: Ohio | J147: Columbus | K147: Office Supplies | L147: Art | M147: Marker Set | N147: 11 | O147: 0 | P147: 1157.17 | Q147: 164.46
A148: 147 | B148: WS-2023-100147 | C148: 08/07/2023 | D148: 08/13/2023 | E148: First Class | F148: Joseph Lopez | G148: Consumer | H148: West | I148: Washington | J148: Seattle | K148: Technology | L148: Phones | M148: Cordless Phone | N148: 12 | O148: 0.3 | P148: 3121.91 | Q148: 761.8
A150: 148 | B150: WS-2022-100148 | C150: 05/08/2022 | D150: 05/10/2022 | E150: Same Day | F150: Barbara Johnson | G150: Corporate | H150: West | I150: California | J150: Los Angeles | K150: Furniture | L150: Furnishings | M150: Desk Lamp | N150: 2 | O150: 0 | P150: 186.21 | Q150: 3.33
A151: 149 | B151: WT-2023-100149 | C151: 10/29/2023 | D151: 11/01/2023 | E151: Second Class | F151: Barbara Martinez | G151: Consumer | H151: West | I151: Arizona | J151: Phoenix | K151: Furniture | L151: Chairs | M151: Mesh Task Chair | N151: 4 | O151: 0.2 | P151: 2164.47 | Q151: 208.84
A152: 150 | B152: ST-2024-100150 | C152: 07/06/2024 | D152: 07/12/2024 | E152: Same Day | F152: Thomas Hernandez | G152: Home Office | H152: South | I152: North Carolina | J152: Charlotte | K152: Office Supplies | L152: Labels | M152: Address Labels | N152: 7 | O152: 0 | P152: 473.13 | Q152: 157.73
A153: 151 | B153: SS-2023-100151 | C153: 08/28/2023 | D153: 08/30/2023 | E153: Second Class | F153: Karen Wilson | G153: Corporate | H153: South | I153: Georgia | J153: Atlanta | K153: Office Supplies | L153: Paper | M153: Sticky Notes | N153: 14 | O153: 0 | P153: 400.27 | Q153: 93.45
... A202: 199 | B202: CS-2022-100199 | C202: 05/16/2022 | D202: 05/17/2022 | E202: Second Class | F202: Patricia Smith | G202: Home Office | H202: Central | I202: Ohio | J202: Columbus | K202: Office Supplies | L202: Paper | M202: Copy Paper A4 | N202: 7 | O202: 0 | P202: 109.8 | Q202: -7.07
A203: 200 | B203: ET-2023-100200 | C203: 11/26/2023 | D203: 12/03/2023 | E203: Same Day | F203: Patricia Smith | G203: Corporate | H203: East | I203: Pennsylvania | J203: Philadelphia | K203: Office Supplies | L203: Storage | M203: Plastic Bin | N203: 14 | O203: 0 | Q203: -32.76
A204: 201 | B204: CT-2023-100201 | C204: 07/22/2023 | D204: 07/27/2023 | E204: Standard Class | F204: Patricia Jackson | G204: Home Office | H204: Central | I204: Minnesota | J204: Minneapolis | K204: Furniture | L204: Chairs | M204: Recliner Chair | N204: 6 | O204: 0 | P204: 374.53 | Q204: -11.01
A205: 202 | B205: WS-2021-100202 | C205: 04/05/2021 | D205: 04/09/2021 | E205: First Class | F205: Karen Wilson | G205: Consumer | H205: West | I205: Arizona | J205: Phoenix | K205: Furniture | L205: Chairs | M205: Mesh Task Chair | N205: 6 | O205: 0 | P205: 1701.07 | Q205: -242.61
A206: 203 | B206: WS-2021-100203 | C206: 06/09/2021 | D206: 06/14/2021 | E206: First Class | F206: Richard Williams | G206: Corporate | H206: West | I206: Nevada | J206: Las Vegas | K206: Technology | L206: Accessories | M206: Wireless Mouse | N206: 6 | O206: 0 | P206: 516.71 | Q206: -73.58
A207: 204 | B207: CS-2023-100204 | C207: 01/26/2023 | D207: 01/28/2023 | E207: Same Day | F207: Joseph Lopez | G207: Home Office | H207: Central | I207: Michigan | J207: Detroit | K207: Furniture | L207: Furnishings | M207: Desk Lamp | N207: 5 | O207: 0.15 | P207: 1936.59 | Q207: 375.21
A208: 205 | B208: WS-2021-100205 | C208: 01/14/2021 | D208: 01/18/2021 | E208: Same Day | F208: David Smith | G208: Home Office | H208: West | I208: Arizona | J208: Phoenix | K208: Office Supplies | L208: Paper | M208: Copy Paper A4 | N208: 1 | O208: 0.2 | P208: 27.72 | Q208: 3.65
A209: 206 | B209: CS-2023-100206 | C209: 10/05/2023 | D209: 10/06/2023 | E209: First Class | F209: Thomas Wilson | G209: Home Office | H209: Central | I209: Illinois | J209: Chicago | K209: Furniture | L209: Tables | M209: Glass Table | N209: 3 | O209: 0 | P209: 1516.1 | Q209: -339.09
A210: 207 | B210: SS-2024-100207 | C210: 07/29/2024 | D210: 08/05/2024 | E210: First Class | F210: Barbara Martinez | G210: Corporate | H210: South | I210: Florida | J210: Miami | K210: Office Supplies | L210: Labels | M210: Address Labels | N210: 7 | O210: 0 | P210: 75.81 | Q210: 0.83
A211: 208 | B211: SS-2021-100208 | C211: 06/02/2021 | D211: 06/04/2021 | E211: Same Day | F211: Joseph Anderson | G211: Corporate | H211: South | I211: North Carolina | J211: Charlotte | K211: Office Supplies | L211: Storage | M211: Storage Box | N211: 3 | O211: 0 | P211: 282.1 | Q211: -44.22
A212: 209 | B212: ET-2022-100209 | C212: 09/24/2022 | D212: 09/28/2022 | E212: First Class | F212: Nancy Johnson | G212: Consumer | H212: East | I212: Virginia | J212: Richmond | K212: Office Supplies | L212: Paper | M212: Colored Paper Pack | N212: 5 | O212: 0 | P212: 512.96 | Q212: -79.73
A213: 210 | B213: WT-2023-100210 | C213: 11/18/2023 | D213: 11/19/2023 | E213: Second Class | F213: Joseph Moore | G213: Home Office | H213: West | I213: California | J213: Los Angeles | K213: Office Supplies | L213: Storage | M213: Filing Cabinet | N213: 11 | O213: 0 | P213: 409.9 | Q213: -94.83
A214: 211 | B214: ET-2021-100211 | C214: 01/25/2021 | D214: 01/26/2021 | E214: First Class | F214: Susan Williams | G214: Home Office | H214: East | I214: Massachusetts | J214: Boston | K214: Furniture | L214: Tables | M214: Round Conference Table | N214: 14 | O214: 0.1 | Q214: -1286.47
...

Sheet Analysis
A1: Sales Performance Analysis | J1: Helper: Unique Product Totals (used by Top-5 formulas — do not delete)
A2: Source: Sales_Data sheet (cleaned) | All figures update automatically via formulas | J2: Product Name | K2: Total Sales
J3: Address Labels | K3: =SUMIF(Sales_Data!$M$2:$M$511,J3,Sales_Data!$P$2:$P$511) + ROW()/10000000 -> 7981.31
A4: Task 2 — Key Metrics | J4: Bluetooth Headset | K4: =SUMIF(Sales_Data!$M$2:$M$511,J4,Sales_Data!$P$2:$P$511) + ROW()/10000000 -> 6395.71
A5: Total Sales | B5: Total Profit | C5: Average Sales | D5: Highest Sales Value | E5: Total Number of Orders | J5: Calculator | K5: =SUMIF(Sales_Data!$M$2:$M$511,J5,Sales_Data!$P$2:$P$511) + ROW()/10000000 -> 23101.76
A6: =SUM(Sales_Data!P2:P511) -> 642224.04 | B6: =SUM(Sales_Data!Q2:Q511) -> 19216.97 | C6: =AVERAGE(Sales_Data!P2:P511) -> 1259.2628 | D6: =MAX(Sales_Data!P2:P511) -> 8445.82 | E6: =SUMPRODUCT(1/COUNTIF(Sales_Data!B2:B511,Sales_Data!B2:B511)) -> 510 | J6: Colored Paper Pack | K6: =SUMIF(Sales_Data!$M$2:$M$511,J6,Sales_Data!$P$2:$P$511) + ROW()/10000000 -> 6279.66
J7: Copy Paper A4 | K7: =SUMIF(Sales_Data!$M$2:$M$511,J7,Sales_Data!$P$2:$P$511) + ROW()/10000000 -> 4170.72
J8: Cordless Phone | K8: =SUMIF(Sales_Data!$M$2:$M$511,J8,Sales_Data!$P$2:$P$511) + ROW()/10000000 -> 11751.84
A9: Total Sales by Region (Pivot) | J9: Corner Bookcase | K9: =SUMIF(Sales_Data!$M$2:$M$511,J9,Sales_Data!$P$2:$P$511) + ROW()/10000000 -> 24183.97
A10: Region | B10: Total Sales | J10: Desk Lamp | K10: =SUMIF(Sales_Data!$M$2:$M$511,J10,Sales_Data!$P$2:$P$511) + ROW()/10000000 -> 22740.54
A11: Central | B11: =SUMIF(Sales_Data!$H$2:$H$511,A11,Sales_Data!$P$2:$P$511) -> 153164.02 | J11: Desktop Copier | K11: =SUMIF(Sales_Data!$M$2:$M$511,J11,Sales_Data!$P$2:$P$511) + ROW()/10000000 -> 11827.41
A12: East | B12: =SUMIF(Sales_Data!$H$2:$H$511,A12,Sales_Data!$P$2:$P$511) -> 167089.08 | J12: Executive Leather Chair | K12: =SUMIF(Sales_Data!$M$2:$M$511,J12,Sales_Data!$P$2:$P$511) + ROW()/10000000 -> 15379
A13: South | B13: =SUMIF(Sales_Data!$H$2:$H$511,A13,Sales_Data!$P$2:$P$511) -> 135430.23 | J13: Filing Cabinet | K13: =SUMIF(Sales_Data!$M$2:$M$511,J13,Sales_Data!$P$2:$P$511) + ROW()/10000000 -> 6358.09
A14: West | B14: =SUMIF(Sales_Data!$H$2:$H$511,A14,Sales_Data!$P$2:$P$511) -> 186540.71 | J14: Filing Cart | K14: =SUMIF(Sales_Data!$M$2:$M$511,J14,Sales_Data!$P$2:$P$511) + ROW()/10000000 -> 16735.68
J15: Folding Table | K15: =SUMIF(Sales_Data!$M$2:$M$511,J15,Sales_Data!$P$2:$P$511) + ROW()/10000000 -> 40051.85
A16: Total Sales by Category (Pivot) | J16: Glass Table | K16: =SUMIF(Sales_Data!$M$2:$M$511,J16,Sales_Data!$P$2:$P$511) + ROW()/10000000 -> 24951
A17: Category | B17: Total Sales | J17: Heavy-Duty Binder | K17: =SUMIF(Sales_Data!$M$2:$M$511,J17,Sales_Data!$P$2:$P$511) + ROW()/10000000 -> 5125.47
A18: Furniture | B18: =SUMIF(Sales_Data!$K$2:$K$511,A18,Sales_Data!$P$2:$P$511) -> 322178.6 | J18: Highlighter Pack | K18: =SUMIF(Sales_Data!$M$2:$M$511,J18,Sales_Data!$P$2:$P$511) + ROW()/10000000 -> 7753.28
A19: Office Supplies | B19: =SUMIF(Sales_Data!$K$2:$K$511,A19,Sales_Data!$P$2:$P$511) -> 134855.32 | J19: Keyboard | K19: =SUMIF(Sales_Data!$M$2:$M$511,J19,Sales_Data!$P$2:$P$511) + ROW()/10000000 -> 13652.35
A20: Technology | B20: =SUMIF(Sales_Data!$K$2:$K$511,A20,Sales_Data!$P$2:$P$511) -> 185190.12 | J20: Label Maker | K20: =SUMIF(Sales_Data!$M$2:$M$511,J20,Sales_Data!$P$2:$P$511) + ROW()/10000000 -> 20559.03
J21: Laminator | K21: =SUMIF(Sales_Data!$M$2:$M$511,J21,Sales_Data!$P$2:$P$511) + ROW()/10000000 -> 23342
A22: Profit by Region (Pivot) | J22: Marker Set | K22: =SUMIF(Sales_Data!$M$2:$M$511,J22,Sales_Data!$P$2:$P$511) + ROW()/10000000 -> 6890.32
A23: Region | B23: Total Profit | J23: Mesh Task Chair | K23: =SUMIF(Sales_Data!$M$2:$M$511,J23,Sales_Data!$P$2:$P$511) + ROW()/10000000 -> 23368.52
A24: Central | B24: =SUMIF(Sales_Data!$H$2:$H$511,A24,Sales_Data!$Q$2:$Q$511) -> 4715.52 | J24: Metal Bookcase | K24: =SUMIF(Sales_Data!$M$2:$M$511,J24,Sales_Data!$P$2:$P$511) + ROW()/10000000 -> 26213.22
A25: East | B25: =SUMIF(Sales_Data!$H$2:$H$511,A25,Sales_Data!$Q$2:$Q$511) -> 4582.21 | J25: Office Copier Pro | K25: =SUMIF(Sales_Data!$M$2:$M$511,J25,Sales_Data!$P$2:$P$511) + ROW()/10000000 -> 44492.59
A26: South | B26: =SUMIF(Sales_Data!$H$2:$H$511,A26,Sales_Data!$Q$2:$Q$511) -> 8040.78 | J26: Paper Clips | K26: =SUMIF(Sales_Data!$M$2:$M$511,J26,Sales_Data!$P$2:$P$511) + ROW()/10000000 -> 8791.29
A27: West | B27: =SUMIF(Sales_Data!$H$2:$H$511,A27,Sales_Data!$Q$2:$Q$511) -> 1878.46 | J27: Picture Frame | K27: =SUMIF(Sales_Data!$M$2:$M$511,J27,Sales_Data!$P$2:$P$511) + ROW()/10000000 -> 15849.98
J28: Plastic Bin | K28: =SUMIF(Sales_Data!$M$2:$M$511,J28,Sales_Data!$P$2:$P$511) + ROW()/10000000 -> 8123.37
A29: Profit by Category (Pivot) | J29: Push Pins | K29: =SUMIF(Sales_Data!$M$2:$M$511,J29,Sales_Data!$P$2:$P$511) + ROW()/10000000 -> 9640.6
A30: Category | B30: Total Profit | J30: Recliner Chair | K30: =SUMIF(Sales_Data!$M$2:$M$511,J30,Sales_Data!$P$2:$P$511) + ROW()/10000000 -> 7456.59
A31: Furniture | B31: =SUMIF(Sales_Data!$K$2:$K$511,A31,Sales_Data!$Q$2:$Q$511) -> 9365.65 | J31: Rectangular Desk | K31: =SUMIF(Sales_Data!$M$2:$M$511,J31,Sales_Data!$P$2:$P$511) + ROW()/10000000 -> 25142.01
A32: Office Supplies | B32: =SUMIF(Sales_Data!$K$2:$K$511,A32,Sales_Data!$Q$2:$Q$511) -> 10043.06 | J32: Round Conference Table | K32: =SUMIF(Sales_Data!$M$2:$M$511,J32,Sales_Data!$P$2:$P$511) + ROW()/10000000 -> 13188.96
A33: Technology | B33: =SUMIF(Sales_Data!$K$2:$K$511,A33,Sales_Data!$Q$2:$Q$511) -> -191.74 | J33: Round Ring Binder | K33: =SUMIF(Sales_Data!$M$2:$M$511,J33,Sales_Data!$P$2:$P$511) + ROW()/10000000 -> 8830.23
J34: Shipping Labels | K34: =SUMIF(Sales_Data!$M$2:$M$511,J34,Sales_Data!$P$2:$P$511) + ROW()/10000000 -> 13753.34
A35: Top 5 Products by Sales (Pivot) | J35: Sketch Pad | K35: =SUMIF(Sales_Data!$M$2:$M$511,J35,Sales_Data!$P$2:$P$511) + ROW()/10000000 -> 4748.01
A36: Product Name | B36: Total Sales | J36: Smartphone X200 | K36: =SUMIF(Sales_Data!$M$2:$M$511,J36,Sales_Data!$P$2:$P$511) + ROW()/10000000 -> 20252.51
A37: =INDEX($J$3:$J$45,MATCH(C37,$K$3:$K$45,0)) -> Office Copier Pro | B37: =ROUNDDOWN(C37,2) -> 44492.59 | C37: =LARGE($K$3:$K$45,1) -> 44492.59 | J37: Stacking Chair | K37: =SUMIF(Sales_Data!$M$2:$M$511,J37,Sales_Data!$P$2:$P$511) + ROW()/10000000 -> 6723.8
A38: =INDEX($J$3:$J$45,MATCH(C38,$K$3:$K$45,0)) -> Folding Table | B38: =ROUNDDOWN(C38,2) -> 40051.85 | C38: =LARGE($K$3:$K$45,2) -> 40051.85 | J38: Stapler | K38: =SUMIF(Sales_Data!$M$2:$M$511,J38,Sales_Data!$P$2:$P$511) + ROW()/10000000 -> 16507.99
A39: =INDEX($J$3:$J$45,MATCH(C39,$K$3:$K$45,0)) -> Wooden Bookcase 5-Shelf | B39: =ROUNDDOWN(C39,2) -> 36860.45 | C39: =LARGE($K$3:$K$45,3) -> 36860.45 | J39: Sticky Notes | K39: =SUMIF(Sales_Data!$M$2:$M$511,J39,Sales_Data!$P$2:$P$511) + ROW()/10000000 -> 5335.7
A40: =INDEX($J$3:$J$45,MATCH(C40,$K$3:$K$45,0)) -> Metal Bookcase | B40: =ROUNDDOWN(C40,2) -> 26213.22 | C40: =LARGE($K$3:$K$45,4) -> 26213.22 | J40: Storage Box | K40: =SUMIF(Sales_Data!$M$2:$M$511,J40,Sales_Data!$P$2:$P$511) + ROW()/10000000 -> 5334.36
...

Sheet Dashboard
A1: Superstore Sales — Mini Dashboard
A2: All figures are live formulas linked to Sales_Data. Use the Region filter below to explore.
A4: Total Sales | C4: Total Profit | E4: Region Filter (Slicer)
A5: =SUM(Sales_Data!P2:P511) -> 642224.04 | C5: =SUM(Sales_Data!Q2:Q511) -> 19216.97 | E5: All
E6: =IF(E5="All",SUM(Sales_Data!P2:P511),SUMIF(Sales_Data!$H$2:$H$511,E5,Sales_Data!$P$2:$P$511)) -> 642224.04
A25: Category | B25: Sales
A26: =Analysis!A18 -> Furniture | B26: =Analysis!B18 -> 322178.6
A27: =Analysis!A19 -> Office Supplies | B27: =Analysis!B19 -> 134855.32
A28: =Analysis!A20 -> Technology | B28: =Analysis!B20 -> 185190.12

Sheet Insights
A1: Insight Questions & Answers
A3: Q | B3: Question | C3: Answer (live formula)
A4: 1 | B4: Which region has the highest sales? | C4: =INDEX(Analysis!A11:A14,MATCH(MAX(Analysis!B11:B14),Analysis!B11:B14,0)) -> West
A5: 2 | B5: Which category generates the most profit? | C5: =INDEX(Analysis!A31:A33,MATCH(MAX(Analysis!B31:B33),Analysis!B31:B33,0)) -> Office Supplies
A6: 3 | B6: Which month has the highest sales? | C6: =INDEX(Analysis!A45:A92,MATCH(MAX(Analysis!B45:B92),Analysis!B45:B92,0)) -> 2024-11
A7: 4 | B7: Which category is underperforming (lowest profit)? | C7: =INDEX(Analysis!A31:A33,MATCH(MIN(Analysis!B31:B33),Analysis!B31:B33,0)) -> Technology
A10: Note: answers are formula-driven (INDEX/MATCH against the pivot tables in 'Analysis') so they update automatically if Sales_Data changes.
